Workbook
Name _: Backend!$M$3:$M$18
Name Customer_First_: Backend!$J$3:$J$6
Name Employees___Learning_: Backend!$L$3:$L$6
Name Finance_: Backend!$I$3:$I$6
Name Internal_processes_: Backend!$K$3:$K$6
Name Slicer_BSC_Focus_area: #N/A
Name Slicer_BSC_Focus_area1: #N/A
Name Slicer_BSC_Perspective: #N/A
Name Slicer_BSC_Perspective1: #N/A
Name Slicer_CSF_Title: #N/A
Name Slicer_CSF_Title1: #N/A
Name Slicer_CSF_Type: #N/A
Name Slicer_CSF_Type1: #N/A
Name Slicer_Responsible: #N/A
Name Slicer_Responsible1: #N/A
Name Table1: Table3[]

Sheet BP Actions
Q2: Color code and definition
Q3: 1 | R3: 1 | S3: Define
Q4: 2 | R4: 2 | S4: Plan
Q5: 3 | R5: 3 | S5: Communicate
Q6: 4 | R6: 4 | S6: Do
Q7: 5 | R7: 5 | S7: Follow-up
B9: BSC | C9: # | D9: BSC Perspective | E9: BSC Focus area | F9: CSF Type | G9: CSF Title | H9: CSF and Actions | I9: Impact | J9: Responsible | K9: Participants | L9: Start | M9: Finish | N9: Comments | O9: Completion rate | Q9: 36 | R9: 37 | S9: 38 | T9: 39 | U9: 40 | V9: 41 | W9: 42 | X9: 43 | Y9: 44 | Z9: 45 | AA9: 46 | AB9: 47 | AC9: 48 | AD9: 49 | AE9: 50 | AF9: 51 | AG9: 52 | AH9: 1 | AI9: 2 | AJ9: 3 | AK9: 4 | AL9: 5 | AM9: 6 | AN9: 7 | AO9: 8 | AP9: 9 | AQ9: 10 | AR9: 11 | AS9: 12 | AT9: 13 | AU9: 14 | AV9: 15 | AW9: 16 | AX9: 17 | AY9: 18 | AZ9: 19 | BA9: 20 | BB9: 21 | BC9: 22 | BD9: 23 | BE9: 24 | BF9: 25 | BG9: 26 | BH9: 27 | BI9: 28 | BJ9: 29 | BK9: 30 | BL9: 31 | BM9: 32 | BN9: 33 | BO9: 34 | BP9: 35
C10: 1 | D10: Finance | E10: Even better cost management | F10: JYSK | G10: Fit for the future | H10: Fit for the future | J10: SSUC
C11: 1.1 | D11: Finance | E11: Even better cost management | F11: JYSK | G11: Fit for the future | H11: Reduce Staff cost | J11: SSUC
C12: 1.1.1 | D12: Finance | E12: Even better cost management | F12: JYSK | G12: Fit for the future | H12: Quarterly optimise number of employees based on turnover | I12: Index productivity (JSI 109,5; JHR 106,9; JBA 109,6; JRS 109,3; JWB 108,7) | J12: SSUC | K12: CD, HOR | L12: W46 | M12: W21 | AA12: 5 | AO12: 5 | BB12: 5
C13: 1.1.2 | D13: Finance | E13: Even better cost management | F13: JYSK | G13: Fit for the future | H13: Refresh staff clothes policy and follow up on ordering and costs | I13: Clothes saving -7.000 eur | J13: SSUC | K13: SCM | L13: W36 | M13: W21 | Q13: 1 | R13: 2 | T13: 4 | AA13: 5 | AO13: 5 | BB13: 5
C14: 1.2 | D14: Finance | E14: Even better cost management | F14: JYSK | G14: Fit for the future | H14: Reduce Premise cost by reducing electricity consumption | I14: Electricity saving -28.000 eur | J14: SSUC
C15: 1.2.1 | D15: Finance | E15: Even better cost management | F15: JYSK | G15: Fit for the future | H15: Define 10% bottom stores in electricity consumption on quarterly base | J15: SSUC | K15: FC, RC | L15: W46 | M15: W21 | AA15: 3 | AO15: 3 | BB15: 3
C16: 1.2.2 | D16: Finance | E16: Even better cost management | F16: JYSK | G16: Fit for the future | H16: Define actions to reduce consumption | J16: SSUC | K16: FC, RC | L16: W47 | M16: W25 | AB16: 4 | AC16: 4 | AD16: 4 | AE16: 4 | AP16: 4 | AQ16: 4 | AR16: 4 | AS16: 4 | BC16: 4 | BD16: 4 | BE16: 4 | BF16: 4
C17: 1.2.3 | D17: Finance | E17: Even better cost management | F17: JYSK | G17: Fit for the future | H17: Quarterly follow up on improvment | J17: SSUC | K17: FC, RC | L17: W46 | M17: W21 | AA17: 5 | AO17: 5 | BB17: 5
C18: 1.3 | D18: Finance | E18: Even better cost management | F18: JYSK | G18: Fit for the future | H18: Reduce Premise cost by reducing waste costs | I18: Waste saving -19.000 | J18: SSUC
C19: 1.3.1 | D19: Finance | E19: Even better cost management | F19: JYSK | G19: Fit for the future | H19: Choose one bottom store per district and analyze consumption | J19: SSUC | K19: RC | L19: W46 | M19: W21 | AA19: 3 | AO19: 3 | BB19: 3
C20: 1.3.2 | D20: Finance | E20: Even better cost management | F20: JYSK | G20: Fit for the future | H20: Define actions to reduce consumption | J20: SSUC | L20: W47 | M20: W25 | AB20: 4 | AC20: 4 | AD20: 4 | AE20: 4 | AP20: 4 | AQ20: 4 | AR20: 4 | AS20: 4 | BC20: 4 | BD20: 4 | BE20: 4 | BF20: 4
C21: 1.3.3 | D21: Finance | E21: Even better cost management | F21: JYSK | G21: Fit for the future | H21: Quarterly follow up on improvment | J21: SSUC | K21: FC, RC | L21: W46 | M21: W21 | AA21: 5 | AO21: 5 | BB21: 5
C22: 1.4 | D22: Finance | E22: Even better cost management | F22: JYSK | G22: Fit for the future | H22: Reduce Premise cost by focusing on maintenance costs | I22: Maintenance saving -22.000 | J22: SSUC
C23: 1.4.1 | D23: Finance | E23: Even better cost management | F23: JYSK | G23: Fit for the future | H23: Analyse number of regular store visits and supplier conditions | J23: SSUC | L23: W35 | M23: W38 | P23: 1 | Q23: 2
C24: 1.4.2 | D24: Finance | E24: Even better cost management | F24: JYSK | G24: Fit for the future | H24: Prepare actions according to findings from analyse | J24: SSUC | K24: OA | L24: W35 | M24: W38 | R24: 4
C25: 1.5 | D25: Finance | E25: Even better cost management | F25: JYSK | G25: Fit for the future | H25: Reduce administrative cost | I25: Stationary saving -25.000 | J25: SSUC
C26: 1.5.1 | D26: Finance | E26: Even better cost management | F26: JYSK | G26: Fit for the future | H26: Prepare guideline for new office supplies supplier | J26: SSUC | K26: OA | L26: W36 | M26: W38 | P26: 1 | Q26: 2 | S26: 3
C27: 1.5.2 | D27: Finance | E27: Even better cost management | F27: JYSK | G27: Fit for the future | H27: Send to DM's consumption of office supplies by stores and follow up on quarterly base | J27: SSUC | K27: RC | L27: W39 | M27: W21 | T27: 5 | AA27: 5 | AO27: 5 | BB27: 5
C28: 1.6 | D28: Finance | E28: Even better cost management | F28: JYSK | G28: Fit for the future | H28: Reduce investment costs | I28: Investment savings - 50.000 eur | J28: SSUC
C29: 1.6.1 | D29: Finance | E29: Even better cost management | F29: JYSK | G29: Fit for the future | H29: Put additional focus on investement costs by regulary benchmark of external supplier prices | J29: SSUC | L29: W39 | M29: W24 | T29: 4 | V29: 4 | AA29: 4 | AE29: 4 | AJ29: 4 | AO29: 4 | AS29: 4 | AW29: 4 | BB29: 4 | BE29: 4
C30: 2 | D30: Internal processes | E30: Attractive stores | F30: JYSK | G30: Optimise Retail Operations | H30: Optimise Retail Operations | I30: Index productivity (JSI 109,5; JHR 106,9; JBA 109,6; JRS 109,3; JWB 108,7) | J30: DEL
C31: 2.1 | D31: Internal processes | E31: Attractive stores | F31: JYSK | G31: Optimise Retail Operations | H31: Implement new goals setup | J31: DEL
C32: 2.1.1 | D32: Internal processes | E32: Attractive stores | F32: JYSK | G32: Optimise Retail Operations | H32: Prepare training/communication materials for new goals/KPI setup | J32: DEL | K32: RC, DM, SM | L32: W35 | M32: W36 | P32: 1 | Q32: 2
C33: 2.1.2 | D33: Internal processes | E33: Attractive stores | F33: JYSK | G33: Optimise Retail Operations | H33: Present and train DMs (National Retail Meeting) and SMs (Country SM meeting) | J33: DEL | K33: RC, DM, SM | L33: W37 | M33: W39 | R33: 4 | T33: 4
C34: 2.1.3 | D34: Internal processes | E34: Attractive stores | F34: JYSK | G34: Optimise Retail Operations | H34: SMs present and train all store staff | J34: DEL | K34: RC, DM, SM | L34: W40 | M34: W44 | U34: 4 | V34: 4 | W34: 4 | X34: 4 | Y34: 4
C35: 2.1.4 | D35: Internal processes | E35: Attractive stores | F35: JYSK | G35: Optimise Retail Operations | H35: DMs follow up on understanding during GSM days | J35: DEL | K35: RC, DM, SM | L35: W45 | M35: W18 | Z35: 5 | AA35: 5 | AB35: 5 | AC35: 5 | AD35: 5 | AE35: 5 | AF35: 5 | AG35: 5 | AH35: 5 | AI35: 5 | AJ35: 5 | AK35: 5 | AL35: 5 | AM35: 5 | AN35: 5 | AO35: 5 | AP35: 5 | AQ35: 5 | AR35: 5 | AS35: 5 | AT35: 5 | AU35: 5 | AV35: 5 | AW35: 5 | AX35: 5 | AY35: 5
C36: 2.2 | D36: Internal processes | E36: Attractive stores | F36: JYSK | G36: Optimise Retail Operations | H36: Optimise store communication | J36: DEL
C37: 2.2.1 | D37: Internal processes | E37: Attractive stores | F37: JYSK | G37: Optimise Retail Operations | H37: Define 1 store communication ambassador (RM) per country and describe the new role | J37: DEL | K37: RM, DM | L37: W35 | M37: W36 | P37: 1 | Q37: 2
C38: 2.2.2 | D38: Internal processes | E38: Attractive stores | F38: JYSK | G38: Optimise Retail Operations | H38: Present new role to admin users and train them in correct usage of all communication channels | J38: DEL | K38: RM, DM | L38: W38 | M38: W38 | R38: 3
C39: 2.2.3 | D39: Internal processes | E39: Attractive stores | F39: JYSK | G39: Optimise Retail Operations | H39: Store communication ambassador analyse once per quarter all communication to the stores | J39: DEL | K39: RM, DM | L39: W45 | M39: W32 | Z39: 5 | AO39: 5 | BB39: 5 | BM39: 5
C40: 2.2.4 | D40: Internal processes | E40: Attractive stores | F40: JYSK | G40: Optimise Retail Operations | H40: Present results to admin users and refresh knowledge about communication to the stores | J40: DEL | K40: RM, DM | L40: W45 | M40: W32 | Z40: 3 | AO40: 3 | BB40: 3 | BM40: 3
C41: 2.3 | D41: Internal processes | E41: Attractive stores | F41: JYSK | G41: Optimise Retail Operations | H41: Minimise locally implemented procedures | J41: DEL
C42: 2.3.1 | D42: Internal processes | E42: Attractive stores | F42: JYSK | G42: Optimise Retail Operations | H42: Create list of all locally implemented procedures | J42: DEL | K42: RSS, DM, IA | L42: W35 | M42: W35 | P42: 1
...

Sheet High-level overview
C9: 3 | D9: 5 | E9: 2 | F9: 3 | G9: 4 | H9: 6 | I9: 8 | J9: 10 | K9: 11 | L9: 12 | M9: 13
C10: Updated automatically from BP Actions sheet - do not change
B11: BSC | C11: # | D11: CSF Title | E11: BSC Perspective | F11: BSC Focus area | G11: CSF Type | H11: CSF or Action | I11: Responsible | J11: Start | K11: Finish | L11: Comments | M11: Completion rate
C12: 1 | D12: =IFERROR(IF(VLOOKUP(Table2[[#This Row],['#]],Table3[['#]:[Completion rate]],'High-level overview'!D$9,FALSE)=0,"",VLOOKUP(Table2[[#This Row],['#]],Table3[['#]:[Completion rate]],'High-level overview'!D$9,FALSE)),"") -> Fit for the future | E12: =IFERROR(IF(VLOOKUP(Table2[[#This Row],['#]],Table3[['#]:[Completion rate]],'High-level overview'!E$9,FALSE)=0,"",VLOOKUP(Table2[[#This Row],['#]],Table3[['#]:[Completion rate]],'High-level overview'!E$9,FALSE)),"") -> Finance | F12: =IFERROR(IF(VLOOKUP(Table2[[#This Row],['#]],Table3[['#]:[Completion rate]],'High-level overview'!F$9,FALSE)=0,"",VLOOKUP(Table2[[#This Row],['#]],Table3[['#]:[Completion rate]],'High-level overview'!F$9,FALSE)),"") -> Even better cost management | G12: =IFERROR(IF(VLOOKUP(Table2[[#This Row],['#]],Table3[['#]:[Completion rate]],'High-level overview'!G$9,FALSE)=0,"",VLOOKUP(Table2[[#This Row],['#]],Table3[['#]:[Completion rate]],'High-level overview'!G$9,FALSE)),"") -> JYSK | H12: =IFERROR(IF(VLOOKUP(Table2[[#This Row],['#]],Table3[['#]:[Completion rate]],'High-level overview'!H$9,FALSE)=0,"",VLOOKUP(Table2[[#This Row],['#]],Table3[['#]:[Completion rate]],'High-level overview'!H$9,FALSE)),"") -> Fit for the future | I12: =IFERROR(IF(VLOOKUP(Table2[[#This Row],['#]],Table3[['#]:[Completion rate]],'High-level overview'!I$9,FALSE)=0,"",VLOOKUP(Table2[[#This Row],['#]],Table3[['#]:[Completion rate]],'High-level overview'!I$9,FALSE)),"") -> SSUC | J12: =IFERROR(IF(VLOOKUP(Table2[[#This Row],['#]],Table3[['#]:[Completion rate]],'High-level overview'!J$9,FALSE)=0,"",VLOOKUP(Table2[[#This Row],['#]],Table3[['#]:[Completion rate]],'High-level overview'!J$9,FALSE)),"") | K12: =IFERROR(IF(VLOOKUP(Table2[[#This Row],['#]],Table3[['#]:[Completion rate]],'High-level overview'!K$9,FALSE)=0,"",VLOOKUP(Table2[[#This Row],['#]],Table3[['#]:[Completion rate]],'High-level overview'!K$9,FALSE)),"") | ... M12: =IFERROR(IF(VLOOKUP(Table2[[#This Row],['#]],Table3[['#]:[Completion rate]],'High-level overview'!M$9,FALSE)=0,"",VLOOKUP(Table2[[#This Row],['#]],Table3[['#]:[Completion rate]],'High-level overview'!M$9,FALSE)),"")
C13: 2 | D13: =IFERROR(IF(VLOOKUP(Table2[[#This Row],['#]],Table3[['#]:[Completion rate]],'High-level overview'!D$9,FALSE)=0,"",VLOOKUP(Table2[[#This Row],['#]],Table3[['#]:[Completion rate]],'High-level overview'!D$9,FALSE)),"") -> Optimise Retail Operations | E13: =IFERROR(IF(VLOOKUP(Table2[[#This Row],['#]],Table3[['#]:[Completion rate]],'High-level overview'!E$9,FALSE)=0,"",VLOOKUP(Table2[[#This Row],['#]],Table3[['#]:[Completion rate]],'High-level overview'!E$9,FALSE)),"") -> Internal processes | F13: =IFERROR(IF(VLOOKUP(Table2[[#This Row],['#]],Table3[['#]:[Completion rate]],'High-level overview'!F$9,FALSE)=0,"",VLOOKUP(Table2[[#This Row],['#]],Table3[['#]:[Completion rate]],'High-level overview'!F$9,FALSE)),"") -> Attractive stores | G13: =IFERROR(IF(VLOOKUP(Table2[[#This Row],['#]],Table3[['#]:[Completion rate]],'High-level overview'!G$9,FALSE)=0,"",VLOOKUP(Table2[[#This Row],['#]],Table3[['#]:[Completion rate]],'High-level overview'!G$9,FALSE)),"") -> JYSK | H13: =IFERROR(IF(VLOOKUP(Table2[[#This Row],['#]],Table3[['#]:[Completion rate]],'High-level overview'!H$9,FALSE)=0,"",VLOOKUP(Table2[[#This Row],['#]],Table3[['#]:[Completion rate]],'High-level overview'!H$9,FALSE)),"") -> Optimise Retail Operations | I13: =IFERROR(IF(VLOOKUP(Table2[[#This Row],['#]],Table3[['#]:[Completion rate]],'High-level overview'!I$9,FALSE)=0,"",VLOOKUP(Table2[[#This Row],['#]],Table3[['#]:[Completion rate]],'High-level overview'!I$9,FALSE)),"") -> DEL | J13: =IFERROR(IF(VLOOKUP(Table2[[#This Row],['#]],Table3[['#]:[Completion rate]],'High-level overview'!J$9,FALSE)=0,"",VLOOKUP(Table2[[#This Row],['#]],Table3[['#]:[Completion rate]],'High-level overview'!J$9,FALSE)),"") | K13: =IFERROR(IF(VLOOKUP(Table2[[#This Row],['#]],Table3[['#]:[Completion rate]],'High-level overview'!K$9,FALSE)=0,"",VLOOKUP(Table2[[#This Row],['#]],Table3[['#]:[Completion rate]],'High-level overview'!K$9,FALSE)),"") | ... M13: =IFERROR(IF(VLOOKUP(Table2[[#This Row],['#]],Table3[['#]:[Completion rate]],'High-level overview'!M$9,FALSE)=0,"",VLOOKUP(Table2[[#This Row],['#]],Table3[['#]:[Completion rate]],'High-level overview'!M$9,FALSE)),"")
C14: 3 | D14: =IFERROR(IF(VLOOKUP(Table2[[#This Row],['#]],Table3[['#]:[Completion rate]],'High-level overview'!D$9,FALSE)=0,"",VLOOKUP(Table2[[#This Row],['#]],Table3[['#]:[Completion rate]],'High-level overview'!D$9,FALSE)),"") -> Attract the future | E14: =IFERROR(IF(VLOOKUP(Table2[[#This Row],['#]],Table3[['#]:[Completion rate]],'High-level overview'!E$9,FALSE)=0,"",VLOOKUP(Table2[[#This Row],['#]],Table3[['#]:[Completion rate]],'High-level overview'!E$9,FALSE)),"") -> Employees & learning | F14: =IFERROR(IF(VLOOKUP(Table2[[#This Row],['#]],Table3[['#]:[Completion rate]],'High-level overview'!F$9,FALSE)=0,"",VLOOKUP(Table2[[#This Row],['#]],Table3[['#]:[Completion rate]],'High-level overview'!F$9,FALSE)),"") -> Attractive place to work | G14: =IFERROR(IF(VLOOKUP(Table2[[#This Row],['#]],Table3[['#]:[Completion rate]],'High-level overview'!G$9,FALSE)=0,"",VLOOKUP(Table2[[#This Row],['#]],Table3[['#]:[Completion rate]],'High-level overview'!G$9,FALSE)),"") -> JYSK | H14: =IFERROR(IF(VLOOKUP(Table2[[#This Row],['#]],Table3[['#]:[Completion rate]],'High-level overview'!H$9,FALSE)=0,"",VLOOKUP(Table2[[#This Row],['#]],Table3[['#]:[Completion rate]],'High-level overview'!H$9,FALSE)),"") -> Attract the future | I14: =IFERROR(IF(VLOOKUP(Table2[[#This Row],['#]],Table3[['#]:[Completion rate]],'High-level overview'!I$9,FALSE)=0,"",VLOOKUP(Table2[[#This Row],['#]],Table3[['#]:[Completion rate]],'High-level overview'!I$9,FALSE)),"") -> JCU | J14: =IFERROR(IF(VLOOKUP(Table2[[#This Row],['#]],Table3[['#]:[Completion rate]],'High-level overview'!J$9,FALSE)=0,"",VLOOKUP(Table2[[#This Row],['#]],Table3[['#]:[Completion rate]],'High-level overview'!J$9,FALSE)),"") | K14: =IFERROR(IF(VLOOKUP(Table2[[#This Row],['#]],Table3[['#]:[Completion rate]],'High-level overview'!K$9,FALSE)=0,"",VLOOKUP(Table2[[#This Row],['#]],Table3[['#]:[Completion rate]],'High-level overview'!K$9,FALSE)),"") | ... M14: =IFERROR(IF(VLOOKUP(Table2[[#This Row],['#]],Table3[['#]:[Completion rate]],'High-level overview'!M$9,FALSE)=0,"",VLOOKUP(Table2[[#This Row],['#]],Table3[['#]:[Completion rate]],'High-level overview'!M$9,FALSE)),"")
C15: 4 | D15: =IFERROR(IF(VLOOKUP(Table2[[#This Row],['#]],Table3[['#]:[Completion rate]],'High-level overview'!D$9,FALSE)=0,"",VLOOKUP(Table2[[#This Row],['#]],Table3[['#]:[Completion rate]],'High-level overview'!D$9,FALSE)),"") -> Retain and empower our talent and performers | E15: =IFERROR(IF(VLOOKUP(Table2[[#This Row],['#]],Table3[['#]:[Completion rate]],'High-level overview'!E$9,FALSE)=0,"",VLOOKUP(Table2[[#This Row],['#]],Table3[['#]:[Completion rate]],'High-level overview'!E$9,FALSE)),"") -> Employees & learning | F15: =IFERROR(IF(VLOOKUP(Table2[[#This Row],['#]],Table3[['#]:[Completion rate]],'High-level overview'!F$9,FALSE)=0,"",VLOOKUP(Table2[[#This Row],['#]],Table3[['#]:[Completion rate]],'High-level overview'!F$9,FALSE)),"") -> Attractive place to work | G15: =IFERROR(IF(VLOOKUP(Table2[[#This Row],['#]],Table3[['#]:[Completion rate]],'High-level overview'!G$9,FALSE)=0,"",VLOOKUP(Table2[[#This Row],['#]],Table3[['#]:[Completion rate]],'High-level overview'!G$9,FALSE)),"") -> JYSK | H15: =IFERROR(IF(VLOOKUP(Table2[[#This Row],['#]],Table3[['#]:[Completion rate]],'High-level overview'!H$9,FALSE)=0,"",VLOOKUP(Table2[[#This Row],['#]],Table3[['#]:[Completion rate]],'High-level overview'!H$9,FALSE)),"") -> Retain and empower our talent and performers | I15: =IFERROR(IF(VLOOKUP(Table2[[#This Row],['#]],Table3[['#]:[Completion rate]],'High-level overview'!I$9,FALSE)=0,"",VLOOKUP(Table2[[#This Row],['#]],Table3[['#]:[Completion rate]],'High-level overview'!I$9,FALSE)),"") -> JCU | J15: =IFERROR(IF(VLOOKUP(Table2[[#This Row],['#]],Table3[['#]:[Completion rate]],'High-level overview'!J$9,FALSE)=0,"",VLOOKUP(Table2[[#This Row],['#]],Table3[['#]:[Completion rate]],'High-level overview'!J$9,FALSE)),"") | K15: =IFERROR(IF(VLOOKUP(Table2[[#This Row],['#]],Table3[['#]:[Completion rate]],'High-level overview'!K$9,FALSE)=0,"",VLOOKUP(Table2[[#This Row],['#]],Table3[['#]:[Completion rate]],'High-level overview'!K$9,FALSE)),"") | ... M15: =IFERROR(IF(VLOOKUP(Table2[[#This Row],['#]],Table3[['#]:[Completion rate]],'High-level overview'!M$9,FALSE)=0,"",VLOOKUP(Table2[[#This Row],['#]],Table3[['#]:[Completion rate]],'High-level overview'!M$9,FALSE)),"")
C16: 5 | D16: =IFERROR(IF(VLOOKUP(Table2[[#This Row],['#]],Table3[['#]:[Completion rate]],'High-level overview'!D$9,FALSE)=0,"",VLOOKUP(Table2[[#This Row],['#]],Table3[['#]:[Completion rate]],'High-level overview'!D$9,FALSE)),"") -> Explore, implement and leverage Artificial Intelligence | E16: =IFERROR(IF(VLOOKUP(Table2[[#This Row],['#]],Table3[['#]:[Completion rate]],'High-level overview'!E$9,FALSE)=0,"",VLOOKUP(Table2[[#This Row],['#]],Table3[['#]:[Completion rate]],'High-level overview'!E$9,FALSE)),"") -> Finance | F16: =IFERROR(IF(VLOOKUP(Table2[[#This Row],['#]],Table3[['#]:[Completion rate]],'High-level overview'!F$9,FALSE)=0,"",VLOOKUP(Table2[[#This Row],['#]],Table3[['#]:[Completion rate]],'High-level overview'!F$9,FALSE)),"") -> Sales growth | G16: =IFERROR(IF(VLOOKUP(Table2[[#This Row],['#]],Table3[['#]:[Completion rate]],'High-level overview'!G$9,FALSE)=0,"",VLOOKUP(Table2[[#This Row],['#]],Table3[['#]:[Completion rate]],'High-level overview'!G$9,FALSE)),"") -> Service function | H16: =IFERROR(IF(VLOOKUP(Table2[[#This Row],['#]],Table3[['#]:[Completion rate]],'High-level overview'!H$9,FALSE)=0,"",VLOOKUP(Table2[[#This Row],['#]],Table3[['#]:[Completion rate]],'High-level overview'!H$9,FALSE)),"") -> Explore, implement and leverage Artificial Intelligence | I16: =IFERROR(IF(VLOOKUP(Table2[[#This Row],['#]],Table3[['#]:[Completion rate]],'High-level overview'!I$9,FALSE)=0,"",VLOOKUP(Table2[[#This Row],['#]],Table3[['#]:[Completion rate]],'High-level overview'!I$9,FALSE)),"") | J16: =IFERROR(IF(VLOOKUP(Table2[[#This Row],['#]],Table3[['#]:[Completion rate]],'High-level overview'!J$9,FALSE)=0,"",VLOOKUP(Table2[[#This Row],['#]],Table3[['#]:[Completion rate]],'High-level overview'!J$9,FALSE)),"") | K16: =IFERROR(IF(VLOOKUP(Table2[[#This Row],['#]],Table3[['#]:[Completion rate]],'High-level overview'!K$9,FALSE)=0,"",VLOOKUP(Table2[[#This Row],['#]],Table3[['#]:[Completion rate]],'High-level overview'!K$9,FALSE)),"") | ... M16: =IFERROR(IF(VLOOKUP(Table2[[#This Row],['#]],Table3[['#]:[Completion rate]],'High-level overview'!M$9,FALSE)=0,"",VLOOKUP(Table2[[#This Row],['#]],Table3[['#]:[Completion rate]],'High-level overview'!M$9,FALSE)),"")
C17: 6 | D17: =IFERROR(IF(VLOOKUP(Table2[[#This Row],['#]],Table3[['#]:[Completion rate]],'High-level overview'!D$9,FALSE)=0,"",VLOOKUP(Table2[[#This Row],['#]],Table3[['#]:[Completion rate]],'High-level overview'!D$9,FALSE)),"") -> Secure the voice of the customer through insights | E17: =IFERROR(IF(VLOOKUP(Table2[[#This Row],['#]],Table3[['#]:[Completion rate]],'High-level overview'!E$9,FALSE)=0,"",VLOOKUP(Table2[[#This Row],['#]],Table3[['#]:[Completion rate]],'High-level overview'!E$9,FALSE)),"") -> Finance | F17: =IFERROR(IF(VLOOKUP(Table2[[#This Row],['#]],Table3[['#]:[Completion rate]],'High-level overview'!F$9,FALSE)=0,"",VLOOKUP(Table2[[#This Row],['#]],Table3[['#]:[Completion rate]],'High-level overview'!F$9,FALSE)),"") -> Sales growth | G17: =IFERROR(IF(VLOOKUP(Table2[[#This Row],['#]],Table3[['#]:[Completion rate]],'High-level overview'!G$9,FALSE)=0,"",VLOOKUP(Table2[[#This Row],['#]],Table3[['#]:[Completion rate]],'High-level overview'!G$9,FALSE)),"") -> Service function | H17: =IFERROR(IF(VLOOKUP(Table2[[#This Row],['#]],Table3[['#]:[Completion rate]],'High-level overview'!H$9,FALSE)=0,"",VLOOKUP(Table2[[#This Row],['#]],Table3[['#]:[Completion rate]],'High-level overview'!H$9,FALSE)),"") -> Secure the voice of the customer through insights | I17: =IFERROR(IF(VLOOKUP(Table2[[#This Row],['#]],Table3[['#]:[Completion rate]],'High-level overview'!I$9,FALSE)=0,"",VLOOKUP(Table2[[#This Row],['#]],Table3[['#]:[Completion rate]],'High-level overview'!I$9,FALSE)),"") | J17: =IFERROR(IF(VLOOKUP(Table2[[#This Row],['#]],Table3[['#]:[Completion rate]],'High-level overview'!J$9,FALSE)=0,"",VLOOKUP(Table2[[#This Row],['#]],Table3[['#]:[Completion rate]],'High-level overview'!J$9,FALSE)),"") | K17: =IFERROR(IF(VLOOKUP(Table2[[#This Row],['#]],Table3[['#]:[Completion rate]],'High-level overview'!K$9,FALSE)=0,"",VLOOKUP(Table2[[#This Row],['#]],Table3[['#]:[Completion rate]],'High-level overview'!K$9,FALSE)),"") | ... M17: =IFERROR(IF(VLOOKUP(Table2[[#This Row],['#]],Table3[['#]:[Completion rate]],'High-level overview'!M$9,FALSE)=0,"",VLOOKUP(Table2[[#This Row],['#]],Table3[['#]:[Completion rate]],'High-level overview'!M$9,FALSE)),"")
C18: 7 | D18: =IFERROR(IF(VLOOKUP(Table2[[#This Row],['#]],Table3[['#]:[Completion rate]],'High-level overview'!D$9,FALSE)=0,"",VLOOKUP(Table2[[#This Row],['#]],Table3[['#]:[Completion rate]],'High-level overview'!D$9,FALSE)),"") -> Make JYSK more sustainable | E18: =IFERROR(IF(VLOOKUP(Table2[[#This Row],['#]],Table3[['#]:[Completion rate]],'High-level overview'!E$9,FALSE)=0,"",VLOOKUP(Table2[[#This Row],['#]],Table3[['#]:[Completion rate]],'High-level overview'!E$9,FALSE)),"") -> Finance | F18: =IFERROR(IF(VLOOKUP(Table2[[#This Row],['#]],Table3[['#]:[Completion rate]],'High-level overview'!F$9,FALSE)=0,"",VLOOKUP(Table2[[#This Row],['#]],Table3[['#]:[Completion rate]],'High-level overview'!F$9,FALSE)),"") -> Sales growth | G18: =IFERROR(IF(VLOOKUP(Table2[[#This Row],['#]],Table3[['#]:[Completion rate]],'High-level overview'!G$9,FALSE)=0,"",VLOOKUP(Table2[[#This Row],['#]],Table3[['#]:[Completion rate]],'High-level overview'!G$9,FALSE)),"") -> Service function | H18: =IFERROR(IF(VLOOKUP(Table2[[#This Row],['#]],Table3[['#]:[Completion rate]],'High-level overview'!H$9,FALSE)=0,"",VLOOKUP(Table2[[#This Row],['#]],Table3[['#]:[Completion rate]],'High-level overview'!H$9,FALSE)),"") -> Make JYSK more sustainable | I18: =IFERROR(IF(VLOOKUP(Table2[[#This Row],['#]],Table3[['#]:[Completion rate]],'High-level overview'!I$9,FALSE)=0,"",VLOOKUP(Table2[[#This Row],['#]],Table3[['#]:[Completion rate]],'High-level overview'!I$9,FALSE)),"") | J18: =IFERROR(IF(VLOOKUP(Table2[[#This Row],['#]],Table3[['#]:[Completion rate]],'High-level overview'!J$9,FALSE)=0,"",VLOOKUP(Table2[[#This Row],['#]],Table3[['#]:[Completion rate]],'High-level overview'!J$9,FALSE)),"") | K18: =IFERROR(IF(VLOOKUP(Table2[[#This Row],['#]],Table3[['#]:[Completion rate]],'High-level overview'!K$9,FALSE)=0,"",VLOOKUP(Table2[[#This Row],['#]],Table3[['#]:[Completion rate]],'High-level overview'!K$9,FALSE)),"") | ... M18: =IFERROR(IF(VLOOKUP(Table2[[#This Row],['#]],Table3[['#]:[Completion rate]],'High-level overview'!M$9,FALSE)=0,"",VLOOKUP(Table2[[#This Row],['#]],Table3[['#]:[Completion rate]],'High-level overview'!M$9,FALSE)),"")
C19: 8 | D19: =IFERROR(IF(VLOOKUP(Table2[[#This Row],['#]],Table3[['#]:[Completion rate]],'High-level overview'!D$9,FALSE)=0,"",VLOOKUP(Table2[[#This Row],['#]],Table3[['#]:[Completion rate]],'High-level overview'!D$9,FALSE)),"") -> Enhance benefits from RTM | E19: =IFERROR(IF(VLOOKUP(Table2[[#This Row],['#]],Table3[['#]:[Completion rate]],'High-level overview'!E$9,FALSE)=0,"",VLOOKUP(Table2[[#This Row],['#]],Table3[['#]:[Completion rate]],'High-level overview'!E$9,FALSE)),"") -> Finance | F19: =IFERROR(IF(VLOOKUP(Table2[[#This Row],['#]],Table3[['#]:[Completion rate]],'High-level overview'!F$9,FALSE)=0,"",VLOOKUP(Table2[[#This Row],['#]],Table3[['#]:[Completion rate]],'High-level overview'!F$9,FALSE)),"") -> Sales growth | G19: =IFERROR(IF(VLOOKUP(Table2[[#This Row],['#]],Table3[['#]:[Completion rate]],'High-level overview'!G$9,FALSE)=0,"",VLOOKUP(Table2[[#This Row],['#]],Table3[['#]:[Completion rate]],'High-level overview'!G$9,FALSE)),"") -> Service function | H19: =IFERROR(IF(VLOOKUP(Table2[[#This Row],['#]],Table3[['#]:[Completion rate]],'High-level overview'!H$9,FALSE)=0,"",VLOOKUP(Table2[[#This Row],['#]],Table3[['#]:[Completion rate]],'High-level overview'!H$9,FALSE)),"") -> Enhance benefits from RTM | I19: =IFERROR(IF(VLOOKUP(Table2[[#This Row],['#]],Table3[['#]:[Completion rate]],'High-level overview'!I$9,FALSE)=0,"",VLOOKUP(Table2[[#This Row],['#]],Table3[['#]:[Completion rate]],'High-level overview'!I$9,FALSE)),"") | J19: =IFERROR(IF(VLOOKUP(Table2[[#This Row],['#]],Table3[['#]:[Completion rate]],'High-level overview'!J$9,FALSE)=0,"",VLOOKUP(Table2[[#This Row],['#]],Table3[['#]:[Completion rate]],'High-level overview'!J$9,FALSE)),"") | K19: =IFERROR(IF(VLOOKUP(Table2[[#This Row],['#]],Table3[['#]:[Completion rate]],'High-level overview'!K$9,FALSE)=0,"",VLOOKUP(Table2[[#This Row],['#]],Table3[['#]:[Completion rate]],'High-level overview'!K$9,FALSE)),"") | ... M19: =IFERROR(IF(VLOOKUP(Table2[[#This Row],['#]],Table3[['#]:[Completion rate]],'High-level overview'!M$9,FALSE)=0,"",VLOOKUP(Table2[[#This Row],['#]],Table3[['#]:[Completion rate]],'High-level overview'!M$9,FALSE)),"")
C20: 9 | D20: =IFERROR(IF(VLOOKUP(Table2[[#This Row],['#]],Table3[['#]:[Completion rate]],'High-level overview'!D$9,FALSE)=0,"",VLOOKUP(Table2[[#This Row],['#]],Table3[['#]:[Completion rate]],'High-level overview'!D$9,FALSE)),"") -> Upgrade web shops to 3.0 | E20: =IFERROR(IF(VLOOKUP(Table2[[#This Row],['#]],Table3[['#]:[Completion rate]],'High-level overview'!E$9,FALSE)=0,"",VLOOKUP(Table2[[#This Row],['#]],Table3[['#]:[Completion rate]],'High-level overview'!E$9,FALSE)),"") -> Customer first | F20: =IFERROR(IF(VLOOKUP(Table2[[#This Row],['#]],Table3[['#]:[Completion rate]],'High-level overview'!F$9,FALSE)=0,"",VLOOKUP(Table2[[#This Row],['#]],Table3[['#]:[Completion rate]],'High-level overview'!F$9,FALSE)),"") -> Easy shopping | G20: =IFERROR(IF(VLOOKUP(Table2[[#This Row],['#]],Table3[['#]:[Completion rate]],'High-level overview'!G$9,FALSE)=0,"",VLOOKUP(Table2[[#This Row],['#]],Table3[['#]:[Completion rate]],'High-level overview'!G$9,FALSE)),"") -> Service function | H20: =IFERROR(IF(VLOOKUP(Table2[[#This Row],['#]],Table3[['#]:[Completion rate]],'High-level overview'!H$9,FALSE)=0,"",VLOOKUP(Table2[[#This Row],['#]],Table3[['#]:[Completion rate]],'High-level overview'!H$9,FALSE)),"") -> Upgrade web shops to 3.0 | I20: =IFERROR(IF(VLOOKUP(Table2[[#This Row],['#]],Table3[['#]:[Completion rate]],'High-level overview'!I$9,FALSE)=0,"",VLOOKUP(Table2[[#This Row],['#]],Table3[['#]:[Completion rate]],'High-level overview'!I$9,FALSE)),"") | J20: =IFERROR(IF(VLOOKUP(Table2[[#This Row],['#]],Table3[['#]:[Completion rate]],'High-level overview'!J$9,FALSE)=0,"",VLOOKUP(Table2[[#This Row],['#]],Table3[['#]:[Completion rate]],'High-level overview'!J$9,FALSE)),"") | K20: =IFERROR(IF(VLOOKUP(Table2[[#This Row],['#]],Table3[['#]:[Completion rate]],'High-level overview'!K$9,FALSE)=0,"",VLOOKUP(Table2[[#This Row],['#]],Table3[['#]:[Completion rate]],'High-level overview'!K$9,FALSE)),"") | ... M20: =IFERROR(IF(VLOOKUP(Table2[[#This Row],['#]],Table3[['#]:[Completion rate]],'High-level overview'!M$9,FALSE)=0,"",VLOOKUP(Table2[[#This Row],['#]],Table3[['#]:[Completion rate]],'High-level overview'!M$9,FALSE)),"")
C21: 10 | D21: =IFERROR(IF(VLOOKUP(Table2[[#This Row],['#]],Table3[['#]:[Completion rate]],'High-level overview'!D$9,FALSE)=0,"",VLOOKUP(Table2[[#This Row],['#]],Table3[['#]:[Completion rate]],'High-level overview'!D$9,FALSE)),"") -> Improve delivery stability and service | E21: =IFERROR(IF(VLOOKUP(Table2[[#This Row],['#]],Table3[['#]:[Completion rate]],'High-level overview'!E$9,FALSE)=0,"",VLOOKUP(Table2[[#This Row],['#]],Table3[['#]:[Completion rate]],'High-level overview'!E$9,FALSE)),"") -> Internal processes | F21: =IFERROR(IF(VLOOKUP(Table2[[#This Row],['#]],Table3[['#]:[Completion rate]],'High-level overview'!F$9,FALSE)=0,"",VLOOKUP(Table2[[#This Row],['#]],Table3[['#]:[Completion rate]],'High-level overview'!F$9,FALSE)),"") -> Balanced flow of goods | G21: =IFERROR(IF(VLOOKUP(Table2[[#This Row],['#]],Table3[['#]:[Completion rate]],'High-level overview'!G$9,FALSE)=0,"",VLOOKUP(Table2[[#This Row],['#]],Table3[['#]:[Completion rate]],'High-level overview'!G$9,FALSE)),"") -> Service function | H21: =IFERROR(IF(VLOOKUP(Table2[[#This Row],['#]],Table3[['#]:[Completion rate]],'High-level overview'!H$9,FALSE)=0,"",VLOOKUP(Table2[[#This Row],['#]],Table3[['#]:[Completion rate]],'High-level overview'!H$9,FALSE)),"") -> Improve delivery stability and service | I21: =IFERROR(IF(VLOOKUP(Table2[[#This Row],['#]],Table3[['#]:[Completion rate]],'High-level overview'!I$9,FALSE)=0,"",VLOOKUP(Table2[[#This Row],['#]],Table3[['#]:[Completion rate]],'High-level overview'!I$9,FALSE)),"") | J21: =IFERROR(IF(VLOOKUP(Table2[[#This Row],['#]],Table3[['#]:[Completion rate]],'High-level overview'!J$9,FALSE)=0,"",VLOOKUP(Table2[[#This Row],['#]],Table3[['#]:[Completion rate]],'High-level overview'!J$9,FALSE)),"") | K21: =IFERROR(IF(VLOOKUP(Table2[[#This Row],['#]],Table3[['#]:[Completion rate]],'High-level overview'!K$9,FALSE)=0,"",VLOOKUP(Table2[[#This Row],['#]],Table3[['#]:[Completion rate]],'High-level overview'!K$9,FALSE)),"") | ... M21: =IFERROR(IF(VLOOKUP(Table2[[#This Row],['#]],Table3[['#]:[Completion rate]],'High-level overview'!M$9,FALSE)=0,"",VLOOKUP(Table2[[#This Row],['#]],Table3[['#]:[Completion rate]],'High-level overview'!M$9,FALSE)),"")
C22: 11 | D22: =IFERROR(IF(VLOOKUP(Table2[[#This Row],['#]],Table3[['#]:[Completion rate]],'High-level overview'!D$9,FALSE)=0,"",VLOOKUP(Table2[[#This Row],['#]],Table3[['#]:[Completion rate]],'High-level overview'!D$9,FALSE)),"") -> Simplify communication to stores | E22: =IFERROR(IF(VLOOKUP(Table2[[#This Row],['#]],Table3[['#]:[Completion rate]],'High-level overview'!E$9,FALSE)=0,"",VLOOKUP(Table2[[#This Row],['#]],Table3[['#]:[Completion rate]],'High-level overview'!E$9,FALSE)),"") -> Internal processes | F22: =IFERROR(IF(VLOOKUP(Table2[[#This Row],['#]],Table3[['#]:[Completion rate]],'High-level overview'!F$9,FALSE)=0,"",VLOOKUP(Table2[[#This Row],['#]],Table3[['#]:[Completion rate]],'High-level overview'!F$9,FALSE)),"") -> Attractive stores | G22: =IFERROR(IF(VLOOKUP(Table2[[#This Row],['#]],Table3[['#]:[Completion rate]],'High-level overview'!G$9,FALSE)=0,"",VLOOKUP(Table2[[#This Row],['#]],Table3[['#]:[Completion rate]],'High-level overview'!G$9,FALSE)),"") -> Service function | H22: =IFERROR(IF(VLOOKUP(Table2[[#This Row],['#]],Table3[['#]:[Completion rate]],'High-level overview'!H$9,FALSE)=0,"",VLOOKUP(Table2[[#This Row],['#]],Table3[['#]:[Completion rate]],'High-level overview'!H$9,FALSE)),"") -> Simplify communication to stores | I22: =IFERROR(IF(VLOOKUP(Table2[[#This Row],['#]],Table3[['#]:[Completion rate]],'High-level overview'!I$9,FALSE)=0,"",VLOOKUP(Table2[[#This Row],['#]],Table3[['#]:[Completion rate]],'High-level overview'!I$9,FALSE)),"") | J22: =IFERROR(IF(VLOOKUP(Table2[[#This Row],['#]],Table3[['#]:[Completion rate]],'High-level overview'!J$9,FALSE)=0,"",VLOOKUP(Table2[[#This Row],['#]],Table3[['#]:[Completion rate]],'High-level overview'!J$9,FALSE)),"") | K22: =IFERROR(IF(VLOOKUP(Table2[[#This Row],['#]],Table3[['#]:[Completion rate]],'High-level overview'!K$9,FALSE)=0,"",VLOOKUP(Table2[[#This Row],['#]],Table3[['#]:[Completion rate]],'High-level overview'!K$9,FALSE)),"") | ... M22: =IFERROR(IF(VLOOKUP(Table2[[#This Row],['#]],Table3[['#]:[Completion rate]],'High-level overview'!M$9,FALSE)=0,"",VLOOKUP(Table2[[#This Row],['#]],Table3[['#]:[Completion rate]],'High-level overview'!M$9,FALSE)),"")
C23: 12 | D23: =IFERROR(IF(VLOOKUP(Table2[[#This Row],['#]],Table3[['#]:[Completion rate]],'High-level overview'!D$9,FALSE)=0,"",VLOOKUP(Table2[[#This Row],['#]],Table3[['#]:[Completion rate]],'High-level overview'!D$9,FALSE)),"") -> Improve situation-based marketing and branding | E23: =IFERROR(IF(VLOOKUP(Table2[[#This Row],['#]],Table3[['#]:[Completion rate]],'High-level overview'!E$9,FALSE)=0,"",VLOOKUP(Table2[[#This Row],['#]],Table3[['#]:[Completion rate]],'High-level overview'!E$9,FALSE)),"") -> Internal processes | F23: =IFERROR(IF(VLOOKUP(Table2[[#This Row],['#]],Table3[['#]:[Completion rate]],'High-level overview'!F$9,FALSE)=0,"",VLOOKUP(Table2[[#This Row],['#]],Table3[['#]:[Completion rate]],'High-level overview'!F$9,FALSE)),"") -> Effective marketing | G23: =IFERROR(IF(VLOOKUP(Table2[[#This Row],['#]],Table3[['#]:[Completion rate]],'High-level overview'!G$9,FALSE)=0,"",VLOOKUP(Table2[[#This Row],['#]],Table3[['#]:[Completion rate]],'High-level overview'!G$9,FALSE)),"") -> Service function | H23: =IFERROR(IF(VLOOKUP(Table2[[#This Row],['#]],Table3[['#]:[Completion rate]],'High-level overview'!H$9,FALSE)=0,"",VLOOKUP(Table2[[#This Row],['#]],Table3[['#]:[Completion rate]],'High-level overview'!H$9,FALSE)),"") -> Improve situation-based marketing and branding | I23: =IFERROR(IF(VLOOKUP(Table2[[#This Row],['#]],Table3[['#]:[Completion rate]],'High-level overview'!I$9,FALSE)=0,"",VLOOKUP(Table2[[#This Row],['#]],Table3[['#]:[Completion rate]],'High-level overview'!I$9,FALSE)),"") | J23: =IFERROR(IF(VLOOKUP(Table2[[#This Row],['#]],Table3[['#]:[Completion rate]],'High-level overview'!J$9,FALSE)=0,"",VLOOKUP(Table2[[#This Row],['#]],Table3[['#]:[Completion rate]],'High-level overview'!J$9,FALSE)),"") | K23: =IFERROR(IF(VLOOKUP(Table2[[#This Row],['#]],Table3[['#]:[Completion rate]],'High-level overview'!K$9,FALSE)=0,"",VLOOKUP(Table2[[#This Row],['#]],Table3[['#]:[Completion rate]],'High-level overview'!K$9,FALSE)),"") | ... M23: =IFERROR(IF(VLOOKUP(Table2[[#This Row],['#]],Table3[['#]:[Completion rate]],'High-level overview'!M$9,FALSE)=0,"",VLOOKUP(Table2[[#This Row],['#]],Table3[['#]:[Completion rate]],'High-level overview'!M$9,FALSE)),"")
... C51: 40 | D51: =IFERROR(IF(VLOOKUP(Table2[[#This Row],['#]],Table3[['#]:[Completion rate]],'High-level overview'!D$9,FALSE)=0,"",VLOOKUP(Table2[[#This Row],['#]],Table3[['#]:[Completion rate]],'High-level overview'!D$9,FALSE)),"") | E51: =IFERROR(IF(VLOOKUP(Table2[[#This Row],['#]],Table3[['#]:[Completion rate]],'High-level overview'!E$9,FALSE)=0,"",VLOOKUP(Table2[[#This Row],['#]],Table3[['#]:[Completion rate]],'High-level overview'!E$9,FALSE)),"") | F51: =IFERROR(IF(VLOOKUP(Table2[[#This Row],['#]],Table3[['#]:[Completion rate]],'High-level overview'!F$9,FALSE)=0,"",VLOOKUP(Table2[[#This Row],['#]],Table3[['#]:[Completion rate]],'High-level overview'!F$9,FALSE)),"") | G51: =IFERROR(IF(VLOOKUP(Table2[[#This Row],['#]],Table3[['#]:[Completion rate]],'High-level overview'!G$9,FALSE)=0,"",VLOOKUP(Table2[[#This Row],['#]],Table3[['#]:[Completion rate]],'High-level overview'!G$9,FALSE)),"") | H51: =IFERROR(IF(VLOOKUP(Table2[[#This Row],['#]],Table3[['#]:[Completion rate]],'High-level overview'!H$9,FALSE)=0,"",VLOOKUP(Table2[[#This Row],['#]],Table3[['#]:[Completion rate]],'High-level overview'!H$9,FALSE)),"") | I51: =IFERROR(IF(VLOOKUP(Table2[[#This Row],['#]],Table3[['#]:[Completion rate]],'High-level overview'!I$9,FALSE)=0,"",VLOOKUP(Table2[[#This Row],['#]],Table3[['#]:[Completion rate]],'High-level overview'!I$9,FALSE)),"") | J51: =IFERROR(IF(VLOOKUP(Table2[[#This Row],['#]],Table3[['#]:[Completion rate]],'High-level overview'!J$9,FALSE)=0,"",VLOOKUP(Table2[[#This Row],['#]],Table3[['#]:[Completion rate]],'High-level overview'!J$9,FALSE)),"") | K51: =IFERROR(IF(VLOOKUP(Table2[[#This Row],['#]],Table3[['#]:[Completion rate]],'High-level overview'!K$9,FALSE)=0,"",VLOOKUP(Table2[[#This Row],['#]],Table3[['#]:[Completion rate]],'High-level overview'!K$9,FALSE)),"") | ... M51: =IFERROR(IF(VLOOKUP(Table2[[#This Row],['#]],Table3[['#]:[Completion rate]],'High-level overview'!M$9,FALSE)=0,"",VLOOKUP(Table2[[#This Row],['#]],Table3[['#]:[Completion rate]],'High-level overview'!M$9,FALSE)),"")

Sheet Quick guide
A1: Quick guide
A2: Excel sheet:

Sheet Backend
O1: Completion rate
B2: Type of CSF | D2: Perspective | F2: Focus Area | I2: Finance | J2: Customer first | K2: Internal processes | L2: Employees & learning | O2: 1
B3: JYSK | D3: Finance | F3: Even better cost management | I3: Even better cost management | J3: Reliable product quality | K3: Balanced flow of goods | L3: Strong talent pipeline | M3: Even better cost management | O3: 0.75
B4: Service Function | D4: Customer first | F4: Improve earnings | I4: Improve earnings | J4: Easy shopping | K4: Relevant assortment | L4: Relevant training | M4: Improve earnings | O4: 0.5
B5: Local | D5: Internal processes | F5: Sales growth | I5: Sales growth | J5: Competent service | K5: Attractive stores | L5: Great store management | M5: Sales growth | O5: 0.25
D6: Employees & learning | F6: Expansion | I6: Expansion | J6: Seamless cross channel | K6: Effective marketing | L6: Attractive place to work | M6: Expansion | O6: Not started
F7: Reliable product quality | M7: Reliable product quality | O7: Not relevant
F8: Easy shopping | M8: Easy shopping
F9: Competent service | M9: Competent service
F10: Seamless cross channel | I10: RGB | M10: Seamless cross channel
F11: Balanced flow of goods | I11: 252 | J11: 197 | K11: 176 | L11: 223 | M11: Balanced flow of goods
F12: Relevant assortment | I12: 209 | J12: 222 | K12: 203 | L12: 142 | M12: Relevant assortment
F13: Attractive stores | I13: 99 | J13: 239 | K13: 169 | L13: 120 | M13: Attractive stores
F14: Effective marketing | M14: Effective marketing
F15: Strong talent pipeline | M15: Strong talent pipeline
F16: Relevant training | M16: Relevant training
F17: Great store management | M17: Great store management
F18: Attractive place to work | M18: Attractive place to work
I23: Formulas for conditional formatting of perspectives
I24: =OR(AND($D10="Finance",$E10="Even better cost management"),AND($D10="Finance",$E10="Improve earnings"),AND($D10="Finance",$E10="Sales Growth"),AND($D10="Finance",$E10="Expansion")) -> FALSE
I25: =OR(AND($D10="Customer first",$E10="Reliable product quality"),AND($D10="Customer first",$E10="Easy shopping"),AND($D10="Customer first",$E10="Competent service"),AND($D10="Customer first",$E10="Seamless cross channel")) -> FALSE
I26: =OR(AND($D10="Internal processes",$E10="Balanced flow of goods"),AND($D10="Internal processes",$E10="Relevant assortment"),AND($D10="Internal processes",$E10="Attractive stores"),AND($D10="Internal processes",$E10="Effective marketing")) -> FALSE
I27: =OR(AND($D10="Employees & learning",$E10="Strong talent pipeline"),AND($D10="Employees & learning",$E10="Relevant training"),AND($D10="Employees & learning",$E10="Great store management"),AND($D10="Employees & learning",$E10="Attractive place to work")) -> FALSE
